Workbook

Sheet Price List
A2: Manufactur | B2: Part # | C2: QTL Cost With MHSW | D2: MHSW | E2: QTL Cost Without MHSW | F2: List Price | G2: Baldwin | H2: Donaldson | I2: Fleetguard
A3: Air Filter | B3: 03-36867-010 | C3: 345 | D3: 355 in np | K3: Counter | L3: Counter | M3: Void | N3: Void
A4: Air Filter | B4: 03-42776-010 | C4: 115 | K4: 1----10 | L4: 7 | M4: 1---20 | N4: 5
A5: Air Filter | B5: 03-43216-010 | C5: 165.31 | K5: 10---15 | L5: 8 | M5: 20---35 | N5: 10
A6: Air Filter | B6: 21715813 | C6: 114.08 | K6: 15---20 | L6: 9 | M6: 35---50 | N6: 15
A7: Air Filter | B7: 23883251 | C7: 301.78
A8: Air Filter | B8: 2515573C1 | C8: 181.62 | K8: 20---25 | L8: 10 | M8: 50---70 | N8: 20
A9: Air Filter | B9: 2599273C92 | C9: 591.98 | K9: 25---30 | L9: 11 | M9: 70---90 | N9: 25
A10: Air Filter | B10: 4329012482 | C10: 95.69 | D10: 84.97 in np
A11: Air Filter | B11: 950011-G3 | C11: 22.52 | K11: 30---35 | L11: 12 | M11: 90---110 | N11: 30
A12: Air Filter | B12: AC1001 | C12: 70.95 | D12: 52.99 in np | K12: 35---40 | L12: 13
A13: Air Filter | B13: AD27747 | C13: =D13+E13 -> 45.7696 | E13: =F13*0.32 -> 45.7696 | F13: 143.03
A14: Air Filter | B14: AD27750 | C14: =D14+E14 -> 46.256 | E14: =F14*0.32 -> 46.256 | F14: 144.55
A15: Air Filter | B15: AF1651 | C15: 6.49
A16: Air Filter | B16: AF25139M | C16: =D16+E16 -> 55.4176 | E16: =F16*0.32 -> 55.4176 | F16: 173.18
A17: Air Filter | B17: AF25550 | C17: =D17+E17 -> 13.2896 | E17: =F17*0.32 -> 13.2896 | F17: 41.53 | K17: 40---45 | L17: 14
A18: Air Filter | B18: AF25707 | C18: =D18+E18 -> 54.2304 | E18: =F18*0.32 -> 54.2304 | F18: 169.47 | K18: 45---50 | L18: 15
A19: Air Filter | B19: AF25732 | C19: =D19+E19 -> 49.8368 | E19: =F19*0.32 -> 49.8368 | F19: 155.74 | K19: 50---60 | L19: 16
A20: Air Filter | B20: AF26163M | C20: =D20+E20 -> 59.776 | E20: =F20*0.32 -> 59.776 | F20: 186.8
A21: Air Filter | B21: AF26268 | C21: =D21+E21 -> 44.6304 | E21: =F21*0.32 -> 44.6304 | F21: 139.47 | K21: 60---70 | L21: 17
A22: Air Filter | B22: AF26403 | C22: =D22+E22 -> 24.2272 | E22: =F22*0.32 -> 24.2272 | F22: 75.71 | K22: 70---80 | L22: 18
A23: Air Filter | B23: AF27690 | C23: =D23+E23 -> 47.7952 | E23: =F23*0.32 -> 47.7952 | F23: 149.36 | K23: 80---90 | L23: 19
A24: Air Filter | B24: AF27693 | C24: =D24+E24 -> 31.3312 | E24: =F24*0.32 -> 31.3312 | F24: 97.91 | K24: 90---100 | L24: 20
A25: Air Filter | B25: AF27905 | C25: =D25+E25 -> 47.136 | E25: =F25*0.32 -> 47.136 | F25: 147.3 | K25: 100--110 | L25: 21
A26: Air Filter | B26: AF27906 | C26: =D26+E26 -> 9.664 | E26: =F26*0.32 -> 9.664 | F26: 30.2 | K26: 110--120 | L26: 22
A27: Air Filter | B27: AF4878 | C27: =D27+E27 -> 28.544 | E27: =F27*0.32 -> 28.544 | F27: 89.2 | K27: 120--130 | L27: 23
A28: Air Filter | B28: AF890 | C28: =D28+E28 -> 69.296 | E28: =F28*0.32 -> 69.296 | F28: 216.55
A29: Air Filter | B29: AH8501 | C29: =D29+E29 -> 143.3376 | E29: =F29*0.32 -> 143.3376 | F29: 447.93
A30: Air Filter | B30: CA30132 | C30: 100.45 | H30: P648156 / P634517
A31: Air Filter | B31: CA4700 | C31: 35.14 | H31: P607955
A32: Air Filter | B32: CA5368 | C32: 54.38 | H32: P607965
A33: Air Filter | B33: CA5500 | C33: 85.87 | H33: P616056
A34: Air Filter | B34: CA5790 | C34: 73.96 | H34: P618478
A35: Air Filter | B35: D37-1061 | C35: 327.43 | K35: D37-1032 | L35: New
A36: Air Filter | B36: ME073821 | C36: 74.4
A37: Air Filter | B37: P129396 | C37: 78.9
A38: Air Filter | B38: P141317 | C38: 67.12 | G38: PA2703
A39: Air Filter | B39: P150695 | C39: 70.13 | G39: PA2680
A40: Air Filter | B40: P151097 | C40: 73.76 | G40: PA3951
A41: Air Filter | B41: P153551 | C41: 52.82 | G41: PA2705
...

Sheet Cost Source
A1: Cost Source | G1: Without Service | S1: With Service
A2: Manufactur | B2: Part # | C2: Type | D2: Spinner | E2: Fuel Filter | F2: Fuel Separator | G2: Oil Filter | H2: Coolant Filter | I2: Air Filter | J2: Cabin Filter | K2: CV Filter | L2: Other | M2: DEF Filter | N2: Over Counter | O2: Labour | P2: Void Price | Q2: Spinner | R2: Fuel Filter | S2: Fuel Separator | T2: Oil Filter | U2: Coolant Filter | V2: Air Filter | W2: Cabin Filter | X2: CV Filter | Y2: Other | Z2: DEF Filter
A3: Air Filter | B3: 03-36867-010 | C3: Air Filter | I3: =V3 -> 55 | N3: 0 | O3: 10 | V3: 55
A4: Air Filter | B4: 03-42776-010 | C4: Air Filter | I4: =V4 -> 55 | N4: 0 | O4: 10 | V4: 55
A5: Air Filter | B5: 03-43216-010 | C5: Air Filter | I5: =V5 -> 55 | N5: 0 | O5: 10 | V5: 55
A6: Air Filter | B6: 21715813 | C6: Air Filter | I6: =V6 -> 30 | N6: 0 | O6: 0 | V6: 30
A7: Air Filter | B7: 23883251 | C7: Air Filter | I7: =V7 -> 58 | V7: 58
A8: Air Filter | B8: 2515573C1 | C8: Air Filter | I8: =V8 -> 50 | N8: 0 | V8: 50
A9: Air Filter | B9: 2599273C92 | C9: Air Filter | I9: =V9 -> 70 | N9: 0 | V9: 70
A10: Air Filter | B10: 4329012482 | C10: Air Dryer Filter ( Webco ) | I10: =V10 -> 30 | N10: 20 | O10: 10 | V10: 30
A11: Air Filter | B11: 950011-G3 | C11: Air Filter | I11: =V11 -> 27 | N11: 0 | V11: 27
A12: Air Filter | B12: AC1001 | C12: Air Dryer Filter( TRP ) | I12: =V12 -> 25 | N12: 15 | O12: 10 | V12: 25
A13: Air Filter | B13: AD27747 | C13: Air Dryer Filter | I13: =V13 -> 30 | N13: 15 | O13: 10 | V13: 30
A14: Air Filter | B14: AD27750 | C14: Air Dryer Filter | I14: =V14 -> 30 | N14: 15 | O14: 10 | V14: 30
A15: Air Filter | B15: AF1651 | C15: Compressor Air Filter | N15: 8
A16: Air Filter | B16: AF25139M | C16: Air Filter | I16: =V16 -> 30 | V16: 30
A17: Air Filter | B17: AF25550 | C17: Air Filter | I17: =V17 -> 20 | N17: 0 | V17: 20
A18: Air Filter | B18: AF25707 | C18: Air Filter | I18: =V18 -> 30 | N18: 0 | V18: 30
A19: Air Filter | B19: AF25732 | C19: Air Filter | I19: =V19 -> 36 | N19: 0 | V19: 36
A20: Air Filter | B20: AF26163M | C20: Air Filter | I20: =V20 -> 30 | V20: 30
A21: Air Filter | B21: AF26268 | C21: Air Filter | I21: =V21 -> 25 | N21: 0 | V21: 25
A22: Air Filter | B22: AF26403 | C22: Air Filter | I22: =V22 -> 22 | N22: 0 | V22: 22
A23: Air Filter | B23: AF27690 | C23: Air Filter | I23: =V23 -> 30 | N23: 0 | V23: 30
A24: Air Filter | B24: AF27693 | C24: Air Filter | I24: =V24 -> 38 | N24: 0 | V24: 38
A25: Air Filter | B25: AF27905 | C25: Air Filter | I25: =V25 -> 56 | N25: 0 | V25: 56
A26: Air Filter | B26: AF27906 | C26: Air Filter | I26: =V26 -> 25 | N26: 0 | V26: 25
A27: Air Filter | B27: AF4878 | C27: Air Filter | I27: =V27 -> 32 | N27: 0 | V27: 32
A28: Air Filter | B28: AF890 | C28: Air Filter | I28: =V28 -> 35 | N28: 0 | V28: 35
A29: Air Filter | B29: AH8501 | C29: Air Filter | I29: =V29 -> 35 | N29: 0 | V29: 35
A30: Air Filter | B30: CA30132 | C30: Air Filter | I30: =V30 -> 48 | N30: 0 | V30: 48
A31: Air Filter | B31: CA4700 | C31: Air Filter | I31: =V31 -> 29 | N31: 0 | V31: 29
A32: Air Filter | B32: CA5368 | C32: Air Filter | I32: =V32 -> 31 | N32: 0 | V32: 31
... A61: Air Filter | B61: P540388 | C61: Air Filter | I61: =V61 -> 30 | N61: 0 | V61: 30
A62: Air Filter | B62: P544243 | C62: Air Filter | I62: 39
A63: Air Filter | B63: P549644 | C63: Air Filter | I63: =V63 -> 40 | N63: 0 | V63: 40
A64: Air Filter | B64: P600676 | C64: Air Filter | I64: =V64 -> 30 | N64: 0 | V64: 30
A65: Air Filter | B65: P606503 | C65: Air Filter | I65: =V65 -> 42 | N65: 0 | V65: 42
A66: Air Filter | B66: P606720 | C66: Air Filter | I66: =V66 -> 30 | N66: 0 | V66: 30
A67: Air Filter | B67: P607955 | C67: Air Filter | I67: =V67 -> 32 | N67: 0 | V67: 32
A68: Air Filter | B68: P607965 | C68: Air Filter | I68: =V68 -> 32 | N68: 0 | V68: 32
...

Sheet All Filter Sell Price
A1: Jan 1,2026
A2: Manufactur | B2: Part # | C2: Without Service Price | D2: Without Service Price | E2: With Service Price | F2: With Service Price | G2: Over Counter Price | H2: Over Counter Price | I2: Void Price | J2: Customer Supplies Filter
A3: Air Filter | B3: 03-36867-010 | C3: ='Price List'!C3+'Cost Source'!I3+'Cost Source'!O3 -> 410 | D3: =ROUNDUP(C3,0)-0.01 -> 409.99 | E3: ='Price List'!C3+'Cost Source'!V3 -> 400 | F3: =ROUNDUP(E3,0)-0.01 -> 399.99 | G3: =E3+'Cost Source'!N3 -> 400 | H3: =ROUNDUP(G3,0)-0.01 -> 399.99 | J3: 20
A4: Air Filter | B4: 03-42776-010 | C4: ='Price List'!C4+'Cost Source'!I4+'Cost Source'!O4 -> 180 | D4: =ROUNDUP(C4,0)-0.01 -> 179.99 | E4: ='Price List'!C4+'Cost Source'!V4 -> 170 | F4: =ROUNDUP(E4,0)-0.01 -> 169.99 | G4: =E4+'Cost Source'!N4 -> 170 | H4: =ROUNDUP(G4,0)-0.01 -> 169.99 | J4: 20
A5: Air Filter | B5: 03-43216-010 | C5: ='Price List'!C5+'Cost Source'!I5+'Cost Source'!O5 -> 230.31 | D5: =ROUNDUP(C5,0)-0.01 -> 230.99 | E5: ='Price List'!C5+'Cost Source'!V5 -> 220.31 | F5: =ROUNDUP(E5,0)-0.01 -> 220.99 | G5: =E5+'Cost Source'!N5 -> 220.31 | H5: =ROUNDUP(G5,0)-0.01 -> 220.99 | J5: 20
A6: Air Filter | B6: 21715813 | C6: ='Price List'!C6+'Cost Source'!I6+'Cost Source'!O6 -> 144.08 | D6: =ROUNDUP(C6,0)-0.01 -> 144.99 | E6: ='Price List'!C6+'Cost Source'!V6 -> 144.08 | F6: =ROUNDUP(E6,0)-0.01 -> 144.99 | G6: =E6+'Cost Source'!N6 -> 144.08 | H6: =ROUNDUP(G6,0)-0.01 -> 144.99 | J6: 10
A7: Air Filter | B7: 23883251 | C7: ='Price List'!C7+'Cost Source'!I7+'Cost Source'!O7 -> 359.78 | D7: =ROUNDUP(C7,0)-0.01 -> 359.99 | E7: ='Price List'!C7+'Cost Source'!V7 -> 359.78 | F7: =ROUNDUP(E7,0)-0.01 -> 359.99 | G7: ='Price List'!C7+'Cost Source'!V7 -> 359.78 | H7: =ROUNDUP(G7,0)-0.01 -> 359.99 | J7: 20
A8: Air Filter | B8: 2515573C1 | C8: ='Price List'!C8+'Cost Source'!I8+'Cost Source'!O8 -> 231.62 | D8: =ROUNDUP(C8,0)-0.01 -> 231.99 | E8: ='Price List'!C8+'Cost Source'!V8 -> 231.62 | F8: =ROUNDUP(E8,0)-0.01 -> 231.99 | G8: =E8+'Cost Source'!N8 -> 231.62 | H8: =ROUNDUP(G8,0)-0.01 -> 231.99 | J8: 10
A9: Air Filter | B9: 2599273C92 | C9: ='Price List'!C9+'Cost Source'!I9+'Cost Source'!O9 -> 661.98 | D9: =ROUNDUP(C9,0)-0.01 -> 661.99 | E9: ='Price List'!C9+'Cost Source'!V9 -> 661.98 | F9: =ROUNDUP(E9,0)-0.01 -> 661.99 | G9: =E9+'Cost Source'!N9 -> 661.98 | H9: =ROUNDUP(G9,0)-0.01 -> 661.99 | J9: 15
A10: Air Filter | B10: 4329012482 | C10: ='Price List'!C10+'Cost Source'!I10+'Cost Source'!O10 -> 135.69 | D10: =ROUNDUP(C10,0)-0.01 -> 135.99 | E10: ='Price List'!C10+'Cost Source'!V10 -> 125.69 | F10: =ROUNDUP(E10,0)-0.01 -> 125.99 | G10: ='Price List'!C10+'Cost Source'!N10 -> 115.69 | H10: =ROUNDUP(G10,0)-0.01 -> 115.99 | J10: 20
A11: Air Filter | B11: 950011-G3 | C11: ='Price List'!C11+'Cost Source'!I11+'Cost Source'!O11 -> 49.52 | D11: =ROUNDUP(C11,0)-0.01 -> 49.99 | E11: ='Price List'!C11+'Cost Source'!V11 -> 49.52 | F11: =ROUNDUP(E11,0)-0.01 -> 49.99 | G11: =E11+'Cost Source'!N11 -> 49.52 | H11: =ROUNDUP(G11,0)-0.01 -> 49.99 | J11: 10
A12: Air Filter | B12: AC1001 | C12: ='Price List'!C12+'Cost Source'!I12+'Cost Source'!O12 -> 105.95 | D12: =ROUNDUP(C12,0)-0.01 -> 105.99 | E12: ='Price List'!C12+'Cost Source'!V12 -> 95.95 | F12: =ROUNDUP(E12,0)-0.01 -> 95.99 | G12: ='Price List'!C12+'Cost Source'!N12 -> 85.95 | H12: =ROUNDUP(G12,0)-0.01 -> 85.99 | J12: 20
A13: Air Filter | B13: AD27747 | C13: ='Price List'!C13+'Cost Source'!I13+'Cost Source'!O13 -> 85.7696 | D13: =ROUNDUP(C13,0)-0.01 -> 85.99 | E13: ='Price List'!C13+'Cost Source'!V13 -> 75.7696 | F13: =ROUNDUP(E13,0)-0.01 -> 75.99 | G13: ='Price List'!C13+'Cost Source'!N13 -> 60.7696 | H13: =ROUNDUP(G13,0)-0.01 -> 60.99 | J13: 20
A14: Air Filter | B14: AD27750 | C14: ='Price List'!C14+'Cost Source'!I14+'Cost Source'!O14 -> 86.256 | D14: =ROUNDUP(C14,0)-0.01 -> 86.99 | E14: ='Price List'!C14+'Cost Source'!V14 -> 76.256 | F14: =ROUNDUP(E14,0)-0.01 -> 76.99 | G14: ='Price List'!C14+'Cost Source'!N14 -> 61.256 | H14: =ROUNDUP(G14,0)-0.01 -> 61.99 | J14: 20
A15: Air Filter | B15: AF1651 | G15: ='Price List'!C15+'Cost Source'!N15 -> 14.49
A16: Air Filter | B16: AF25139M | C16: ='Price List'!C16+'Cost Source'!I16+'Cost Source'!O16 -> 85.4176 | D16: =ROUNDUP(C16,0)-0.01 -> 85.99 | E16: ='Price List'!C16+'Cost Source'!V16 -> 85.4176 | F16: =ROUNDUP(E16,0)-0.01 -> 85.99 | G16: =E16+'Cost Source'!N16 -> 85.4176 | H16: =ROUNDUP(G16,0)-0.01 -> 85.99
A17: Air Filter | B17: AF25550 | C17: ='Price List'!C17+'Cost Source'!I17+'Cost Source'!O17 -> 33.2896 | D17: =ROUNDUP(C17,0)-0.01 -> 33.99 | E17: ='Price List'!C17+'Cost Source'!V17 -> 33.2896 | F17: =ROUNDUP(E17,0)-0.01 -> 33.99 | G17: =E17+'Cost Source'!N17 -> 33.2896 | H17: =ROUNDUP(G17,0)-0.01 -> 33.99 | J17: 10
A18: Air Filter | B18: AF25707 | C18: ='Price List'!C18+'Cost Source'!I18+'Cost Source'!O18 -> 84.2304 | D18: =ROUNDUP(C18,0)-0.01 -> 84.99 | E18: ='Price List'!C18+'Cost Source'!V18 -> 84.2304 | F18: =ROUNDUP(E18,0)-0.01 -> 84.99 | G18: =E18+'Cost Source'!N18 -> 84.2304 | H18: =ROUNDUP(G18,0)-0.01 -> 84.99 | J18: 10
A19: Air Filter | B19: AF25732 | C19: ='Price List'!C19+'Cost Source'!I19+'Cost Source'!O19 -> 85.8368 | D19: =ROUNDUP(C19,0)-0.01 -> 85.99 | E19: ='Price List'!C19+'Cost Source'!V19 -> 85.8368 | F19: =ROUNDUP(E19,0)-0.01 -> 85.99 | G19: =E19+'Cost Source'!N19 -> 85.8368 | H19: =ROUNDUP(G19,0)-0.01 -> 85.99 | J19: 10
A20: Air Filter | B20: AF26163M | C20: ='Price List'!C20+'Cost Source'!I20+'Cost Source'!O20 -> 89.776 | D20: =ROUNDUP(C20,0)-0.01 -> 89.99 | E20: ='Price List'!C20+'Cost Source'!V20 -> 89.776 | F20: =ROUNDUP(E20,0)-0.01 -> 89.99 | G20: =E20+'Cost Source'!N20 -> 89.776 | H20: =ROUNDUP(G20,0)-0.01 -> 89.99
A21: Air Filter | B21: AF26268 | C21: ='Price List'!C21+'Cost Source'!I21+'Cost Source'!O21 -> 69.6304 | D21: =ROUNDUP(C21,0)-0.01 -> 69.99 | E21: ='Price List'!C21+'Cost Source'!V21 -> 69.6304 | F21: =ROUNDUP(E21,0)-0.01 -> 69.99 | G21: =E21+'Cost Source'!N21 -> 69.6304 | H21: =ROUNDUP(G21,0)-0.01 -> 69.99 | J21: 10
A22: Air Filter | B22: AF26403 | C22: ='Price List'!C22+'Cost Source'!I22+'Cost Source'!O22 -> 46.2272 | D22: =ROUNDUP(C22,0)-0.01 -> 46.99 | E22: ='Price List'!C22+'Cost Source'!V22 -> 46.2272 | F22: =ROUNDUP(E22,0)-0.01 -> 46.99 | G22: =E22+'Cost Source'!N22 -> 46.2272 | H22: =ROUNDUP(G22,0)-0.01 -> 46.99 | J22: 10
A23: Air Filter | B23: AF27690 | C23: ='Price List'!C23+'Cost Source'!I23+'Cost Source'!O23 -> 77.7952 | D23: =ROUNDUP(C23,0)-0.01 -> 77.99 | E23: ='Price List'!C23+'Cost Source'!V23 -> 77.7952 | F23: =ROUNDUP(E23,0)-0.01 -> 77.99 | G23: =E23+'Cost Source'!N23 -> 77.7952 | H23: =ROUNDUP(G23,0)-0.01 -> 77.99 | J23: 10
A24: Air Filter | B24: AF27693 | C24: ='Price List'!C24+'Cost Source'!I24+'Cost Source'!O24 -> 69.3312 | D24: =ROUNDUP(C24,0)-0.01 -> 69.99 | E24: ='Price List'!C24+'Cost Source'!V24 -> 69.3312 | F24: =ROUNDUP(E24,0)-0.01 -> 69.99 | G24: =E24+'Cost Source'!N24 -> 69.3312 | H24: =ROUNDUP(G24,0)-0.01 -> 69.99 | J24: 10
A25: Air Filter | B25: AF27905 | C25: ='Price List'!C25+'Cost Source'!I25+'Cost Source'!O25 -> 103.136 | D25: =ROUNDUP(C25,0)-0.01 -> 103.99 | E25: ='Price List'!C25+'Cost Source'!V25 -> 103.136 | F25: =ROUNDUP(E25,0)-0.01 -> 103.99 | G25: =E25+'Cost Source'!N25 -> 103.136 | H25: =ROUNDUP(G25,0)-0.01 -> 103.99 | J25: 10
A26: Air Filter | B26: AF27906 | C26: ='Price List'!C26+'Cost Source'!I26+'Cost Source'!O26 -> 34.664 | D26: =ROUNDUP(C26,0)-0.01 -> 34.99 | E26: ='Price List'!C26+'Cost Source'!V26 -> 34.664 | F26: =ROUNDUP(E26,0)-0.01 -> 34.99 | G26: =E26+'Cost Source'!N26 -> 34.664 | H26: =ROUNDUP(G26,0)-0.01 -> 34.99 | J26: 10
A27: Air Filter | B27: AF4878 | C27: ='Price List'!C27+'Cost Source'!I27+'Cost Source'!O27 -> 60.544 | D27: =ROUNDUP(C27,0)-0.01 -> 60.99 | E27: ='Price List'!C27+'Cost Source'!V27 -> 60.544 | F27: =ROUNDUP(E27,0)-0.01 -> 60.99 | G27: =E27+'Cost Source'!N27 -> 60.544 | H27: =ROUNDUP(G27,0)-0.01 -> 60.99 | J27: 10
A28: Air Filter | B28: AF890 | C28: ='Price List'!C28+'Cost Source'!I28+'Cost Source'!O28 -> 104.296 | D28: =ROUNDUP(C28,0)-0.01 -> 104.99 | E28: ='Price List'!C28+'Cost Source'!V28 -> 104.296 | F28: =ROUNDUP(E28,0)-0.01 -> 104.99 | G28: =E28+'Cost Source'!N28 -> 104.296 | H28: =ROUNDUP(G28,0)-0.01 -> 104.99 | J28: 15
A29: Air Filter | B29: AH8501 | C29: ='Price List'!C29+'Cost Source'!I29+'Cost Source'!O29 -> 178.3376 | D29: =ROUNDUP(C29,0)-0.01 -> 178.99 | E29: ='Price List'!C29+'Cost Source'!V29 -> 178.3376 | F29: =ROUNDUP(E29,0)-0.01 -> 178.99 | G29: =E29+'Cost Source'!N29 -> 178.3376 | H29: =ROUNDUP(G29,0)-0.01 -> 178.99 | J29: 50
A30: Air Filter | B30: CA30132 | C30: ='Price List'!C30+'Cost Source'!I30+'Cost Source'!O30 -> 148.45 | D30: =ROUNDUP(C30,0)-0.01 -> 148.99 | E30: ='Price List'!C30+'Cost Source'!V30 -> 148.45 | F30: =ROUNDUP(E30,0)-0.01 -> 148.99 | G30: =E30+'Cost Source'!N30 -> 148.45 | H30: =ROUNDUP(G30,0)-0.01 -> 148.99
A31: Air Filter | B31: CA4700 | C31: ='Price List'!C31+'Cost Source'!I31+'Cost Source'!O31 -> 64.14 | D31: =ROUNDUP(C31,0)-0.01 -> 64.99 | E31: ='Price List'!C31+'Cost Source'!V31 -> 64.14 | F31: =ROUNDUP(E31,0)-0.01 -> 64.99 | G31: =E31+'Cost Source'!N31 -> 64.14 | H31: =ROUNDUP(G31,0)-0.01 -> 64.99
A32: Air Filter | B32: CA5368 | C32: ='Price List'!C32+'Cost Source'!I32+'Cost Source'!O32 -> 85.38 | D32: =ROUNDUP(C32,0)-0.01 -> 85.99 | E32: ='Price List'!C32+'Cost Source'!V32 -> 85.38 | F32: =ROUNDUP(E32,0)-0.01 -> 85.99 | G32: =E32+'Cost Source'!N32 -> 85.38 | H32: =ROUNDUP(G32,0)-0.01 -> 85.99
A33: Air Filter | B33: CA5500 | C33: ='Price List'!C33+'Cost Source'!I33+'Cost Source'!O33 -> 115.87 | D33: =ROUNDUP(C33,0)-0.01 -> 115.99 | E33: ='Price List'!C33+'Cost Source'!V33 -> 115.87 | F33: =ROUNDUP(E33,0)-0.01 -> 115.99 | G33: =E33+'Cost Source'!N33 -> 115.87 | H33: =ROUNDUP(G33,0)-0.01 -> 115.99
A34: Air Filter | B34: CA5790 | C34: ='Price List'!C34+'Cost Source'!I34+'Cost Source'!O34 -> 100.96 | D34: =ROUNDUP(C34,0)-0.01 -> 100.99 | E34: ='Price List'!C34+'Cost Source'!V34 -> 100.96 | F34: =ROUNDUP(E34,0)-0.01 -> 100.99 | G34: =E34+'Cost Source'!N34 -> 100.96 | H34: =ROUNDUP(G34,0)-0.01 -> 100.99
A35: Air Filter | B35: D37-1061 | C35: ='Price List'!C35+'Cost Source'!I35+'Cost Source'!O35 -> 377.43 | D35: =ROUNDUP(C35,0)-0.01 -> 377.99 | E35: ='Price List'!C35+'Cost Source'!V35 -> 377.43 | F35: =ROUNDUP(E35,0)-0.01 -> 377.99 | G35: =E35+'Cost Source'!N35 -> 377.43 | H35: =ROUNDUP(G35,0)-0.01 -> 377.99
A36: Air Filter | B36: ME073821 | C36: ='Price List'!C36+'Cost Source'!I36 -> 104.4 | D36: =ROUNDUP(C36,0)-0.01 -> 104.99 | E36: ='Price List'!C36+'Cost Source'!V36 -> 104.4 | F36: =ROUNDUP(E36,0)-0.01 -> 104.99 | G36: =E36+'Cost Source'!N36 -> 104.4 | H36: =ROUNDUP(G36,0)-0.01 -> 104.99
A37: Air Filter | B37: P129396 | C37: ='Price List'!C37+'Cost Source'!I37+'Cost Source'!O37 -> 108.9 | D37: =ROUNDUP(C37,0)-0.01 -> 108.99 | E37: ='Price List'!C37+'Cost Source'!V37 -> 108.9 | F37: =ROUNDUP(E37,0)-0.01 -> 108.99 | G37: =E37+'Cost Source'!N37 -> 108.9 | H37: =ROUNDUP(G37,0)-0.01 -> 108.99
A38: Air Filter | B38: P141317 | C38: ='Price List'!C38+'Cost Source'!I38+'Cost Source'!O38 -> 101.12 | D38: =ROUNDUP(C38,0)-0.01 -> 101.99 | E38: ='Price List'!C38+'Cost Source'!V38 -> 101.12 | F38: =ROUNDUP(E38,0)-0.01 -> 101.99 | G38: =E38+'Cost Source'!N38 -> 101.12 | H38: =ROUNDUP(G38,0)-0.01 -> 101.99 | J38: 15
A39: Air Filter | B39: P150695 | C39: ='Price List'!C39+'Cost Source'!I39+'Cost Source'!O39 -> 100.13 | D39: =ROUNDUP(C39,0)-0.01 -> 100.99 | E39: ='Price List'!C39+'Cost Source'!V39 -> 100.13 | F39: =ROUNDUP(E39,0)-0.01 -> 100.99 | G39: =E39+'Cost Source'!N39 -> 100.13 | H39: =ROUNDUP(G39,0)-0.01 -> 100.99
A40: Air Filter | B40: P151097 | C40: ='Price List'!C40+'Cost Source'!I40+'Cost Source'!O40 -> 105.76 | D40: =ROUNDUP(C40,0)-0.01 -> 105.99 | E40: ='Price List'!C40+'Cost Source'!V40 -> 105.76 | F40: =ROUNDUP(E40,0)-0.01 -> 105.99 | G40: =E40+'Cost Source'!N40 -> 105.76 | H40: =ROUNDUP(G40,0)-0.01 -> 105.99
...

Sheet Filter Cost
A1: STANDARD JOB LIST
F2: Filtre
A3: Auto Greaser Refill | F3: Cost
B4: FILTER
B5: Oil | C5: Oil | D5: Fuel | E5: Fuel
A6: C 7 / 10 / 3126 With Cat Filter | B6: 1R1807 | D6: 1R0751
B7: ='Price List'!C175 -> 25.78 | D7: ='Price List'!C174 -> 27.51 | F7: =SUM(B7:E7) -> 53.29 | G7: 53.29 | H7: =F7-G7 -> 0
A8: C 7 / 10 / 3126 With Fleetguard Filter | B8: LF667 | D8: FF5321
B9: ='Price List'!C500 -> 10.484 | D9: ='Price List'!C337 -> 11.3152 | F9: =SUM(B9:E9) -> 21.7992 | G9: 20.61 | H9: =F9-G9 -> 1.1892
A10: C 12 / 3406 With Cat Filter | B10: 1R0716 | D10: 1R0749
B11: ='Price List'!C172 -> 38.44 | D11: ='Price List'!C173 -> 32.14 | F11: =SUM(B11:E11) -> 70.58 | G11: 66.15 | H11: =F11-G11 -> 4.43
A12: C 12 / 3406 With Fleetguard Filter | B12: LF691A | D12: FF5319
B13: ='Price List'!C504 -> 16.8936 | D13: ='Price List'!C335 -> 14.1512 | F13: =SUM(B13:E13) -> 31.0448 | G13: 29.2 | H13: =F13-G13 -> 1.8448
A14: C 13 / 15 With Cat Filter | B14: 1R0716 | D14: 1R0749
B15: ='Price List'!C172 -> 38.44 | D15: ='Price List'!C173 -> 32.14 | F15: =SUM(B15:E15) -> 70.58 | G15: 66.15 | H15: =F15-G15 -> 4.43
A16: C 13 / 15 With Fleetguard Filter | B16: LF691A | D16: FF5319
B17: ='Price List'!C504 -> 16.8936 | D17: ='Price List'!C335 -> 14.1512 | F17: =SUM(B17:E17) -> 31.0448 | G17: 29.2 | H17: =F17-G17 -> 1.8448
A18: Cummins N14 | B18: LF3000
B19: ='Price List'!C472 -> 31.4312 | F19: =SUM(B19:E19) -> 31.4312 | G19: 30.05 | H19: =F19-G19 -> 1.3812
A20: Cummins 5.9L/6.7L | B20: LF3349
B21: ='Price List'!C478 -> 6.72 | F21: =SUM(B21:E21) -> 6.72 | G21: 6.36 | H21: =F21-G21 -> 0.36
A22: Cummins ISC / ISL | B22: LF9009 | D22: FF5636
B23: ='Price List'!C508 -> 32.6664 | D23: ='Price List'!C351 -> 18.144 | F23: =SUM(B23:E23) -> 50.8104 | G23: 48.5 | H23: =F23-G23 -> 2.3104
A24: Cummins ISB | B24: LF3970 | D24: FF5632
B25: ='Price List'!C498 -> 10.5184 | D25: ='Price List'!C350 -> 16.1696 | F25: =SUM(B25:E25) -> 26.688 | G25: 25.3 | H25: =F25-G25 -> 1.388
A26: Cummins ISM | B26: LF14000NN
B27: ='Price List'!C444 -> 39.8344 | F27: =SUM(B27:E27) -> 39.8344 | G27: 38.06 | H27: =F27-G27 -> 1.7744
A28: Cummins ISX | B28: LF14000NN | D28: FF5776
B29: ='Price List'!C444 -> 39.8344 | D29: ='Price List'!C354 -> 45.8152 | F29: =SUM(B29:E29) -> 85.6496 | G29: 81.78 | H29: =F29-G29 -> 3.8696
A30: Cummins M11 | B30: LF3000
B31: ='Price List'!C472 -> 31.4312 | F31: =SUM(B31:E31) -> 31.4312 | G31: 30.05 | H31: =F31-G31 -> 1.3812
A32: Detroit With Detroit Filter | B32: 23530573 | C32: 23530573 | D32: 23530706 | E32: 23530707
B33: ='Price List'!C201 -> 23.15 | C33: ='Price List'!C201 -> 23.15 | D33: ='Price List'!C202 -> 15.42 | E33: ='Price List'!C203 -> 15.9 | F33: =SUM(B33:E33) -> 77.62 | G33: 87.59 | H33: =F33-G33 -> -9.97
A34: Detroit With Detroit Filter (DD8) | B34: A9361807410 | D34: A9360900651
B35: ='Price List'!C242 -> 28.17 | D35: ='Price List'!C241 -> 140.68 | F35: =SUM(B35:E35) -> 168.85 | G35: 168.85 | H35: =F35-G35 -> 0
A36: Detroit With Detroit Filter (DD13,DD15,DD16) | B36: A4731800909 | D36: A4700903151
B37: ='Price List'!C239 -> 37 | D37: ='Price List'!C224 -> 100.79 | F37: =SUM(B37:E37) -> 137.79 | G37: 136.75 | H37: =F37-G37 -> 1.04
A38: Detroit With Fleetguard Filter (DD13,DD15.DD16) | B38: LF17511 | D38: FK13850-NN
B39: ='Price List'!C463 -> 30.6824 | D39: ='Price List'!C366 -> 83.3704 | F39: =SUM(B39:E39) -> 114.0528 | G39: 108.52 | H39: =F39-G39 -> 5.5328
A40: Detroit With Fleetguard | B40: LF3620 | C40: LF3620 | D40: FF5206 | E40: FF5207
...

Sheet 15W40
A1: STANDARD JOB LIST | B1: 15W40 | G1: 4.2 | H1: 0.05
B2: selling | C2: cost | E2: Filtre | F2: Litre | G2: Oil | H2: Fuel | I2: Profit | J2: Cost % | K2: Profit %
A3: Auto Greaser Refill | B3: 39.99 | E3: Cost | G3: Cost | H3: Grease | L3: Last Month | M3: Profit Diff | N3: Last Month | O3: Last Month
A4: Jan 1,2026 | G4: =G1+H1 -> 4.25 | J4: 1 | L4: Profit | N4: Price | O4: Price Diff
A6: C 7 / 10 / 3126 With Cat Filter | B6: 265.99 | C6: =E6+G6+H6 -> 167.54 | E6: ='Filter Cost'!F7 -> 53.29 | F6: 25 | G6: =F6*G4 -> 106.25 | H6: 8 | I6: =B6-C6 -> 98.45 | J6: =C6/B6 -> 0.6298733 | K6: =1-J6 -> 0.3701267 | L6: 98.45 | M6: =I6-L6 -> 0 | N6: 265.99 | O6: =B6-N6 -> 0
A7: C 7 / 10 / 3126 With Fleetguard Filter | B7: 243.99 | C7: =E7+G7+H7 -> 136.0492 | E7: ='Filter Cost'!F9 -> 21.7992 | F7: 25 | G7: =F7*G4 -> 106.25 | H7: 8 | I7: =B7-C7 -> 107.9408 | J7: =C7/B7 -> 0.55760154 | K7: =1-J7 -> 0.44239846 | L7: 106.69 | M7: =I7-L7 -> 1.2508 | N7: 243.99 | O7: =B7-N7 -> 0
A9: C 12 / 3406 With Cat Filter | B9: 334.99 | C9: =E9+G9+H9 -> 240.08 | E9: ='Filter Cost'!F11 -> 70.58 | F9: 38 | G9: =F9*G4 -> 161.5 | H9: 8 | I9: =B9-C9 -> 94.91 | J9: =C9/B9 -> 0.71667811 | K9: =1-J9 -> 0.28332189 | L9: 94.91 | M9: =I9-L9 -> 0 | N9: 334.99 | O9: =B9-N9 -> 0
A10: C 12 / 3406 With Fleetguard Filter | B10: 293.99 | C10: =E10+G10+H10 -> 200.5448 | E10: ='Filter Cost'!F13 -> 31.0448 | F10: 38 | G10: =F10*G4 -> 161.5 | H10: 8 | I10: =B10-C10 -> 93.4452 | J10: =C10/B10 -> 0.68214837 | K10: =1-J10 -> 0.31785163 | L10: 93.35 | M10: =I10-L10 -> 0.0952 | N10: 293.99 | O10: =B10-N10 -> 0
A12: C 13 / 15 With Cat Filter | B12: 354.99 | C12: =E12+G12+H12 -> 261.33 | E12: ='Filter Cost'!F15 -> 70.58 | F12: 43 | G12: =F12*G4 -> 182.75 | H12: 8 | I12: =B12-C12 -> 93.66 | J12: =C12/B12 -> 0.73616158 | K12: =1-J12 -> 0.26383842 | L12: 93.66 | M12: =I12-L12 -> 0 | N12: 354.99 | O12: =B12-N12 -> 0
A13: C 13 / 15 With Fleetguard Filter | B13: 313.99 | C13: =E13+G13+H13 -> 221.7948 | E13: ='Filter Cost'!F17 -> 31.0448 | F13: 43 | G13: =F13*G4 -> 182.75 | H13: 8 | I13: =B13-C13 -> 92.1952 | J13: =C13/B13 -> 0.70637536 | K13: =1-J13 -> 0.29362464 | L13: 92.1 | M13: =I13-L13 -> 0.0952 | N13: 313.99 | O13: =B13-N13 -> 0
A15: Cummins N14 | B15: 301.99 | C15: =E15+G15+H15 -> 209.4312 | E15: ='Filter Cost'!F19 -> 31.4312 | F15: 40 | G15: =F15*G4 -> 170 | H15: 8 | I15: =B15-C15 -> 92.5588 | J15: =C15/B15 -> 0.69350376 | K15: =1-J15 -> 0.30649624 | L15: 92.46 | M15: =I15-L15 -> 0.0988 | N15: 301.99 | O15: =B15-N15 -> 0
A16: Cummins 5.9L/6.7L | B16: 170.99 | C16: =E16+G16+H16 -> 74.22 | E16: ='Filter Cost'!F21 -> 6.72 | F16: 14 | G16: =F16*G4 -> 59.5 | H16: 8 | I16: =B16-C16 -> 96.77 | J16: =C16/B16 -> 0.43406047 | K16: =1-J16 -> 0.56593953 | L16: 96.81 | M16: =I16-L16 -> -0.04 | N16: 170.99 | O16: =B16-N16 -> 0
A17: Cummins ISC / ISL | B17: 257.99 | C17: =E17+G17+H17 -> 165.0604 | E17: ='Filter Cost'!F23 -> 50.8104 | F17: 25 | G17: =F17*G4 -> 106.25 | H17: 8 | I17: =B17-C17 -> 92.9296 | J17: =C17/B17 -> 0.63979379 | K17: =1-J17 -> 0.36020621 | L17: 92.86 | M17: =I17-L17 -> 0.0696 | N17: 257.99 | O17: =B17-N17 -> 0
A18: Cummins ISB | B18: 255.99 | C18: =E18+G18+H18 -> 140.938 | E18: ='Filter Cost'!F25 -> 26.688 | F18: 25 | G18: =F18*G4 -> 106.25 | H18: 8 | I18: =B18-C18 -> 115.052 | J18: =C18/B18 -> 0.55056057 | K18: =1-J18 -> 0.44943943 | L18: 115.07 | M18: =I18-L18 -> -0.018 | N18: 255.99 | O18: =B18-N18 -> 0
A19: Cummins ISM | B19: 292.99 | C19: =E19+G19+H19 -> 200.8344 | E19: ='Filter Cost'!F27 -> 39.8344 | F19: 36 | G19: =F19*G4 -> 153 | H19: 8 | I19: =B19-C19 -> 92.1556 | J19: =C19/B19 -> 0.68546503 | K19: =1-J19 -> 0.31453497 | L19: 92.03 | M19: =I19-L19 -> 0.1256 | N19: 292.99 | O19: =B19-N19 -> 0
A20: Cummins ISX / X15 | B20: 378.99 | C20: =E20+G20+H20 -> 280.6496 | E20: ='Filter Cost'!F29 -> 85.6496 | F20: 44 | G20: =F20*G4 -> 187 | H20: 8 | I20: =B20-C20 -> 98.3404 | J20: =C20/B20 -> 0.7405198 | K20: =1-J20 -> 0.2594802 | L20: 98.06 | M20: =I20-L20 -> 0.2804 | N20: 378.99 | O20: =B20-N20 -> 0
A21: Cummins M11 | B21: 275.99 | C21: =E21+G21+H21 -> 183.9312 | E21: ='Filter Cost'!F31 -> 31.4312 | F21: 34 | G21: =F21*G4 -> 144.5 | H21: 8 | I21: =B21-C21 -> 92.0588 | J21: =C21/B21 -> 0.66644154 | K21: =1-J21 -> 0.33355846 | L21: 91.96 | M21: =I21-L21 -> 0.0988 | N21: 275.99 | O21: =B21-N21 -> 0
A23: Detroit With Detroit Filter | B23: 349.99 | C23: =E23+G23+H23 -> 247.12 | E23: ='Filter Cost'!F33 -> 77.62 | F23: 38 | G23: =F23*G4 -> 161.5 | H23: 8 | I23: =B23-C23 -> 102.87 | J23: =C23/B23 -> 0.70607732 | K23: =1-J23 -> 0.29392268 | L23: 105.87 | M23: =I23-L23 -> -3 | N23: 352.99 | O23: =B23-N23 -> -3
A24: Detroit With Detroit Filter (DD8) | B24: 409.99 | C24: =E24+G24+H24 -> 312.85 | E24: ='Filter Cost'!F35 -> 168.85 | F24: 32 | G24: =F24*G4 -> 136 | H24: 8 | I24: =B24-C24 -> 97.14 | J24: =C24/B24 -> 0.76306739 | K24: =1-J24 -> 0.23693261 | L24: 97.14 | M24: =I24-L24 -> 0 | N24: 409.99 | O24: =B24-N24 -> 0
A25: Detroit With Detroit Filter (DD13,DD15,DD16) | B25: 415.99 | C25: =E25+G25+H25 -> 324.29 | E25: ='Filter Cost'!F37 -> 137.79 | F25: 42 | G25: =F25*G4 -> 178.5 | H25: 8 | I25: =B25-C25 -> 91.7 | J25: =C25/B25 -> 0.77956201 | K25: =1-J25 -> 0.22043799 | L25: 90.84 | M25: =I25-L25 -> 0.86 | N25: 415.99 | O25: =B25-N25 -> 0
A26: Detroit With Fleetguard Filter (DD13,DD15.DD16) | B26: 393.99 | C26: =E26+G26+H26 -> 300.5528 | E26: ='Filter Cost'!F39 -> 114.0528 | F26: 42 | G26: =F26*G4 -> 178.5 | H26: 8 | I26: =B26-C26 -> 93.4372 | J26: =C26/B26 -> 0.76284373 | K26: =1-J26 -> 0.23715627 | L26: 92.77 | M26: =I26-L26 -> 0.6672 | N26: 393.99 | O26: =B26-N26 -> 0
A27: Detroit With Fleetguard | B27: 302.99 | C27: =E27+G27+H27 -> 214.8912 | E27: ='Filter Cost'!F41 -> 45.3912 | F27: 38 | G27: =F27*G4 -> 161.5 | H27: 8 | I27: =B27-C27 -> 88.0988 | J27: =C27/B27 -> 0.70923529 | K27: =1-J27 -> 0.29076471 | L27: 90.07 | M27: =I27-L27 -> -1.9712 | N27: 304.99 | O27: =B27-N27 -> -2
A28: Duramax / Vortec 8100L | B28: 170.99 | C28: =E28+G28+H28 -> 77.6024 | E28: ='Filter Cost'!F43 -> 10.1024 | F28: 14 | G28: =F28*G4 -> 59.5 | H28: 8 | I28: =B28-C28 -> 93.3876 | J28: =C28/B28 -> 0.45384175 | K28: =1-J28 -> 0.54615825 | L28: 93.45 | M28: =I28-L28 -> -0.0624 | N28: 170.99 | O28: =B28-N28 -> 0
A30: F250 / F350 / F550 / F650 | B30: 170.99 | C30: =E30+G30+H30 -> 81.9168 | E30: ='Filter Cost'!F45 -> 14.4168 | F30: 14 | G30: =F30*G4 -> 59.5 | H30: 8 | I30: =B30-C30 -> 89.0732 | J30: =C30/B30 -> 0.47907363 | K30: =1-J30 -> 0.52092637 | L30: 89.16 | M30: =I30-L30 -> -0.0868 | N30: 170.99 | O30: =B30-N30 -> 0
A32: Hino | B32: 269.99 | C32: =E32+G32+H32 -> 163.5 | E32: ='Filter Cost'!F47 -> 96 | F32: 14 | G32: =F32*G4 -> 59.5 | H32: 8 | I32: =B32-C32 -> 106.49 | J32: =C32/B32 -> 0.60557798 | K32: =1-J32 -> 0.39442202 | L32: 106.49 | M32: =I32-L32 -> 0 | N32: 269.99 | O32: =B32-N32 -> 0
A33: Hino With Fleetguard | B33: 199.99 | C33: =E33+G33+H33 -> 94.9216 | E33: ='Filter Cost'!F49 -> 27.4216 | F33: 14 | G33: =F33*G4 -> 59.5 | H33: 8 | I33: =B33-C33 -> 105.0684 | J33: =C33/B33 -> 0.47463173 | K33: =1-J33 -> 0.52536827 | L33: 105.24 | M33: =I33-L33 -> -0.1716 | N33: 199.99 | O33: =B33-N33 -> 0
A35: International | B35: 265.99 | C35: =E35+G35+H35 -> 172.0688 | E35: ='Filter Cost'!F51 -> 53.5688 | F35: 26 | G35: =F35*G4 -> 110.5 | H35: 8 | I35: =B35-C35 -> 93.9212 | J35: =C35/B35 -> 0.64689951 | K35: =1-J35 -> 0.35310049 | L35: 94.15 | M35: =I35-L35 -> -0.2288 | N35: 265.99 | O35: =B35-N35 -> 0
A36: International S13 | B36: 499.99 | C36: =E36+G36+H36 -> 382.3 | E36: ='Filter Cost'!F53 -> 178.8 | F36: 46 | G36: =F36*G4 -> 195.5 | H36: 8 | I36: =B36-C36 -> 117.69 | J36: =C36/B36 -> 0.76461529 | K36: =1-J36 -> 0.23538471 | L36: 117.69
A37: International Vista | B37: 249.99 | C37: =E37+G37+H37 -> 125.3728 | E37: ='Filter Cost'!F55 -> 57.8728 | F37: 14 | G37: =F37*G4 -> 59.5 | H37: 8 | I37: =B37-C37 -> 124.6172 | J37: =C37/B37 -> 0.50151126 | K37: =1-J37 -> 0.49848874
A38: Isuzu With Fleetguard Filter | B38: 215.99 | C38: =E38+G38+H38 -> 111.6408 | E38: ='Filter Cost'!F57 -> 44.1408 | F38: 14 | G38: =F38*G4 -> 59.5 | H38: 8 | I38: =B38-C38 -> 104.3492 | J38: =C38/B38 -> 0.51687949 | K38: =1-J38 -> 0.48312051 | L38: 104.51 | M38: =I38-L38 -> -0.1608 | N38: 215.99 | O38: =B38-N38 -> 0
A39: Isuzu | B39: 275.99 | C39: =E39+G39+H39 -> 136.47 | E39: ='Filter Cost'!F59 -> 68.97 | F39: 14 | G39: =F39*G4 -> 59.5 | H39: 8 | I39: =B39-C39 -> 139.52 | J39: =C39/B39 -> 0.49447444 | K39: =1-J39 -> 0.50552556 | L39: 139.52 | M39: =I39-L39 -> 0 | N39: 275.99 | O39: =B39-N39 -> 0
A41: MP 7 / MP8 With Fleetguard | B41: 363.99 | C41: =E41+G41+H41 -> 256.1048 | E41: ='Filter Cost'!F61 -> 86.6048 | F41: 38 | G41: =F41*G4 -> 161.5 | H41: 8 | I41: =B41-C41 -> 107.8852 | J41: =C41/B41 -> 0.70360395 | K41: =1-J41 -> 0.29639605 | L41: 108.06 | M41: =I41-L41 -> -0.1748 | N41: 363.99 | O41: =B41-N41 -> 0
A42: MP 7 / MP8 With Mack | B42: 434.99 | C42: =E42+G42+H42 -> 343 | E42: ='Filter Cost'!F63 -> 173.5 | F42: 38 | G42: =F42*G4 -> 161.5 | H42: 8 | I42: =B42-C42 -> 91.99 | J42: =C42/B42 -> 0.78852387 | K42: =1-J42 -> 0.21147613 | L42: 84.75 | M42: =I42-L42 -> 7.24 | N42: 419.99 | O42: =B42-N42 -> 15
A43: MP 7/MP8/ MP10 With Fleetguard ( 52L) | B43: 436.99 | C43: =E43+G43+H43 -> 328.3548 | E43: ='Filter Cost'!F61 -> 86.6048 | F43: 55 | G43: =F43*G4 -> 233.75 | H43: 8 | I43: =B43-C43 -> 108.6352 | J43: =C43/B43 -> 0.75140118 | K43: =1-J43 -> 0.24859882 | L43: 108.81 | M43: =I43-L43 -> -0.1748 | N43: 436.99 | O43: =B43-N43 -> 0
A44: MP 7/MP8/ MP10 With Mack (52L) | B44: 509.99 | C44: =E44+G44+H44 -> 415.25 | E44: ='Filter Cost'!F63 -> 173.5 | F44: 55 | G44: =F44*G4 -> 233.75 | H44: 8 | I44: =B44-C44 -> 94.74 | J44: =C44/B44 -> 0.81423165 | K44: =1-J44 -> 0.18576835 | L44: 87.5 | M44: =I44-L44 -> 7.24 | N44: 494.99 | O44: =B44-N44 -> 15
A45: Mack With Fleetguard Filter | B45: 317.99 | C45: =E45+G45+H45 -> 219.884 | E45: ='Filter Cost'!F65 -> 50.384 | F45: 38 | G45: =F45*G4 -> 161.5 | H45: 8 | I45: =B45-C45 -> 98.106 | J45: =C45/B45 -> 0.69148086 | K45: =1-J45 -> 0.30851914 | L45: 98.22 | M45: =I45-L45 -> -0.114 | N45: 317.99 | O45: =B45-N45 -> 0
A46: Mack With Fleetguard Filter(52L) | B46: 377.99 | C46: =E46+G46+H46 -> 279.384 | E46: ='Filter Cost'!F65 -> 50.384 | F46: 52 | G46: =F46*G4 -> 221 | H46: 8 | I46: =B46-C46 -> 98.606 | J46: =C46/B46 -> 0.73913066 | K46: =1-J46 -> 0.26086934 | L46: 98.72 | M46: =I46-L46 -> -0.114 | N46: 377.99 | O46: =B46-N46 -> 0
A47: Mack With Mack Filter | B47: 426.99 | C47: =E47+G47+H47 -> 330.89 | E47: ='Filter Cost'!F67 -> 161.39 | F47: 38 | G47: =F47*G4 -> 161.5 | H47: 8 | I47: =B47-C47 -> 96.1 | J47: =C47/B47 -> 0.77493618 | K47: =1-J47 -> 0.22506382 | L47: 96.1 | M47: =I47-L47 -> 0 | N47: 426.99 | O47: =B47-N47 -> 0
A48: Mack With Mack Filter( 52L ) | B48: 489.99 | C48: =E48+G48+H48 -> 390.39 | E48: ='Filter Cost'!F67 -> 161.39 | F48: 52 | G48: =F48*G4 -> 221 | H48: 8 | I48: =B48-C48 -> 99.6 | J48: =C48/B48 -> 0.79673055 | K48: =1-J48 -> 0.20326945 | L48: 99.6 | M48: =I48-L48 -> 0 | N48: 489.99 | O48: =B48-N48 -> 0
A50: Max Force 7 / 9 / 10 | B50: 435.99 | C50: =E50+G50+H50 -> 341.18 | E50: ='Filter Cost'!F69 -> 222.68 | F50: 26 | G50: =F50*G4 -> 110.5 | H50: 8 | I50: =B50-C50 -> 94.81 | J50: =C50/B50 -> 0.78254088 | K50: =1-J50 -> 0.21745912 | L50: 95.31 | M50: =I50-L50 -> -0.5 | N50: 352.99 | O50: =B50-N50 -> 83 | P50: Fleetguard and OEM Price
...

Sheet 15W40 Gallon
A1: STANDARD JOB LIST | B1: 15W40 | G1: 5.67 | H1: 0.05 | L1: 8--20 | M1: 10
B2: selling | C2: cost | E2: Filtre | F2: Litre | G2: Oil | H2: Fuel | I2: Profit | J2: Cost | K2: Profit | L2: 21--38 | M2: 15
A3: Auto Greaser Refill | E3: Cost | G3: Cost | H3: Grease | L3: 39--46 | M3: 20
G4: =G1+H1 -> 5.72 | J4: 1 | L4: 47& UP | M4: 25
M5: Price Diff | N5: Cost Diff
A6: C 7 / 10 / 3126 With Cat Filter | B6: ='15W40'!B6+('15W40 Gallon'!G4-'15W40'!G4)*'15W40 Gallon'!F6+'15W40 Gallon'!M2 -> 317.74 | C6: =E6+G6+H6 -> 204.29 | E6: ='15W40'!E6 -> 53.29 | F6: ='15W40'!F6 -> 25 | G6: =F6*G4 -> 143 | H6: 8 | I6: =B6-C6 -> 113.45 | J6: =C6/B6 -> 0.64294706 | K6: =1-J6 -> 0.35705294 | M6: =B6-'15W40'!B6 -> 51.75 | N6: =C6-'15W40'!C6 -> 36.75
A7: C 7 / 10 / 3126 With Fleetguard Filter | B7: ='15W40'!B7+('15W40 Gallon'!G4-'15W40'!G4)*'15W40 Gallon'!F7+'15W40 Gallon'!M2 -> 295.74 | C7: =E7+G7+H7 -> 172.7992 | E7: ='15W40'!E7 -> 21.7992 | F7: ='15W40'!F7 -> 25 | G7: =F7*G4 -> 143 | H7: 8 | I7: =B7-C7 -> 122.9408 | J7: =C7/B7 -> 0.58429431 | K7: =1-J7 -> 0.41570569 | M7: =B7-'15W40'!B7 -> 51.75 | N7: =C7-'15W40'!C7 -> 36.75
A9: C 12 / 3406 With Cat Filter | B9: ='15W40'!B9+('15W40 Gallon'!G4-'15W40'!G4)*'15W40 Gallon'!F9+'15W40 Gallon'!M2 -> 405.85 | C9: =E9+G9+H9 -> 295.94 | E9: ='15W40'!E9 -> 70.58 | F9: ='15W40'!F9 -> 38 | G9: =F9*G4 -> 217.36 | H9: 8 | I9: =B9-C9 -> 109.91 | J9: =C9/B9 -> 0.72918566 | K9: =1-J9 -> 0.27081434 | M9: =B9-'15W40'!B9 -> 70.86 | N9: =C9-'15W40'!C9 -> 55.86
A10: C 12 / 3406 With Fleetguard Filter | B10: ='15W40'!B10+('15W40 Gallon'!G4-'15W40'!G4)*'15W40 Gallon'!F10+'15W40 Gallon'!M2 -> 364.85 | C10: =E10+G10+H10 -> 256.4048 | E10: ='15W40'!E10 -> 31.0448 | F10: ='15W40'!F10 -> 38 | G10: =F10*G4 -> 217.36 | H10: 8 | I10: =B10-C10 -> 108.4452 | J10: =C10/B10 -> 0.70276771 | K10: =1-J10 -> 0.29723229 | M10: =B10-'15W40'!B10 -> 70.86 | N10: =C10-'15W40'!C10 -> 55.86
A12: C 13 / 15 With Cat Filter | B12: ='15W40'!B12+('15W40 Gallon'!G4-'15W40'!G4)*'15W40 Gallon'!F12+'15W40 Gallon'!M3 -> 438.2 | C12: =E12+G12+H12 -> 324.54 | E12: ='15W40'!E12 -> 70.58 | F12: ='15W40'!F12 -> 43 | G12: =F12*G4 -> 245.96 | H12: 8 | I12: =B12-C12 -> 113.66 | J12: =C12/B12 -> 0.74062072 | K12: =1-J12 -> 0.25937928 | M12: =B12-'15W40'!B12 -> 83.21 | N12: =C12-'15W40'!C12 -> 63.21
A13: C 13 / 15 With Fleetguard Filter | B13: ='15W40'!B13+('15W40 Gallon'!G4-'15W40'!G4)*'15W40 Gallon'!F13+'15W40 Gallon'!M3 -> 397.2 | C13: =E13+G13+H13 -> 285.0048 | E13: ='15W40'!E13 -> 31.0448 | F13: ='15W40'!F13 -> 43 | G13: =F13*G4 -> 245.96 | H13: 8 | I13: =B13-C13 -> 112.1952 | J13: =C13/B13 -> 0.71753474 | K13: =1-J13 -> 0.28246526 | M13: =B13-'15W40'!B13 -> 83.21 | N13: =C13-'15W40'!C13 -> 63.21
A15: Cummins N14 | B15: ='15W40'!B15+('15W40 Gallon'!G4-'15W40'!G4)*'15W40 Gallon'!F15+'15W40 Gallon'!M3 -> 380.79 | C15: =E15+G15+H15 -> 268.2312 | E15: ='15W40'!E15 -> 31.4312 | F15: ='15W40'!F15 -> 40 | G15: =F15*G4 -> 228.8 | H15: 8 | I15: =B15-C15 -> 112.5588 | J15: =C15/B15 -> 0.70440715 | K15: =1-J15 -> 0.29559285 | M15: =B15-'15W40'!B15 -> 78.8 | N15: =C15-'15W40'!C15 -> 58.8
A16: Cummins 5.9L/6.7L | B16: ='15W40'!B16+('15W40 Gallon'!G4-'15W40'!G4)*'15W40 Gallon'!F16+'15W40 Gallon'!M1 -> 201.57 | C16: =E16+G16+H16 -> 94.8 | E16: ='15W40'!E16 -> 6.72 | F16: ='15W40'!F16 -> 14 | G16: =F16*G4 -> 80.08 | H16: 8 | I16: =B16-C16 -> 106.77 | J16: =C16/B16 -> 0.47030808 | K16: =1-J16 -> 0.52969192 | M16: =B16-'15W40'!B16 -> 30.58 | N16: =C16-'15W40'!C16 -> 20.58
A17: Cummins ISC / ISL | B17: ='15W40'!B17+('15W40 Gallon'!G4-'15W40'!G4)*'15W40 Gallon'!F17+'15W40 Gallon'!M2 -> 309.74 | C17: =E17+G17+H17 -> 201.8104 | E17: ='15W40'!E17 -> 50.8104 | F17: ='15W40'!F17 -> 25 | G17: =F17*G4 -> 143 | H17: 8 | I17: =B17-C17 -> 107.9296 | J17: =C17/B17 -> 0.65154775 | K17: =1-J17 -> 0.34845225 | M17: =B17-'15W40'!B17 -> 51.75 | N17: =C17-'15W40'!C17 -> 36.75
A18: Cummins ISB | B18: ='15W40'!B18+('15W40 Gallon'!G4-'15W40'!G4)*'15W40 Gallon'!F18+'15W40 Gallon'!M2 -> 307.74 | C18: =E18+G18+H18 -> 177.688 | E18: ='15W40'!E18 -> 26.688 | F18: ='15W40'!F18 -> 25 | G18: =F18*G4 -> 143 | H18: 8 | I18: =B18-C18 -> 130.052 | J18: =C18/B18 -> 0.5773965 | K18: =1-J18 -> 0.4226035 | M18: =B18-'15W40'!B18 -> 51.75 | N18: =C18-'15W40'!C18 -> 36.75
A19: Cummins ISM | B19: ='15W40'!B19+('15W40 Gallon'!G4-'15W40'!G4)*'15W40 Gallon'!F19+'15W40 Gallon'!M2 -> 360.91 | C19: =E19+G19+H19 -> 253.7544 | E19: ='15W40'!E19 -> 39.8344 | F19: ='15W40'!F19 -> 36 | G19: =F19*G4 -> 205.92 | H19: 8 | I19: =B19-C19 -> 107.1556 | J19: =C19/B19 -> 0.70309606 | K19: =1-J19 -> 0.29690394 | M19: =B19-'15W40'!B19 -> 67.92 | N19: =C19-'15W40'!C19 -> 52.92
A20: Cummins ISX | B20: ='15W40'!B20+('15W40 Gallon'!G4-'15W40'!G4)*'15W40 Gallon'!F20+'15W40 Gallon'!M3 -> 463.67 | C20: =E20+G20+H20 -> 345.3296 | E20: ='15W40'!E20 -> 85.6496 | F20: ='15W40'!F20 -> 44 | G20: =F20*G4 -> 251.68 | H20: 8 | I20: =B20-C20 -> 118.3404 | J20: =C20/B20 -> 0.74477452 | K20: =1-J20 -> 0.25522548 | M20: =B20-'15W40'!B20 -> 84.68 | N20: =C20-'15W40'!C20 -> 64.68
A21: Cummins M11 | B21: ='15W40'!B21+('15W40 Gallon'!G4-'15W40'!G4)*'15W40 Gallon'!F21+'15W40 Gallon'!M2 -> 340.97 | C21: =E21+G21+H21 -> 233.9112 | E21: ='15W40'!E21 -> 31.4312 | F21: ='15W40'!F21 -> 34 | G21: =F21*G4 -> 194.48 | H21: 8 | I21: =B21-C21 -> 107.0588 | J21: =C21/B21 -> 0.68601695 | K21: =1-J21 -> 0.31398305 | M21: =B21-'15W40'!B21 -> 64.98 | N21: =C21-'15W40'!C21 -> 49.98
A23: Detroit With Detroit Filter | B23: ='15W40'!B23+('15W40 Gallon'!G4-'15W40'!G4)*'15W40 Gallon'!F23+'15W40 Gallon'!M2 -> 420.85 | C23: =E23+G23+H23 -> 302.98 | E23: ='15W40'!E23 -> 77.62 | F23: ='15W40'!F23 -> 38 | G23: =F23*G4 -> 217.36 | H23: 8 | I23: =B23-C23 -> 117.87 | J23: =C23/B23 -> 0.71992396 | K23: =1-J23 -> 0.28007604 | M23: =B23-'15W40'!B23 -> 70.86 | N23: =C23-'15W40'!C23 -> 55.86
A24: Detroit With Detroit Filter (DD8) | B24: ='15W40'!B24+('15W40 Gallon'!G4-'15W40'!G4)*'15W40 Gallon'!F24+'15W40 Gallon'!M2 -> 472.03 | C24: =E24+G24+H24 -> 359.89 | E24: ='15W40'!E24 -> 168.85 | F24: ='15W40'!F24 -> 32 | G24: =F24*G4 -> 183.04 | H24: 8 | I24: =B24-C24 -> 112.14 | J24: =C24/B24 -> 0.76243035 | K24: =1-J24 -> 0.23756965 | M24: =B24-'15W40'!B24 -> 62.04 | N24: =C24-'15W40'!C24 -> 47.04
A25: Detroit With Detroit Filter (DD13,DD15,DD16) | B25: ='15W40'!B25+('15W40 Gallon'!G4-'15W40'!G4)*'15W40 Gallon'!F25+'15W40 Gallon'!M3 -> 497.73 | C25: =E25+G25+H25 -> 386.03 | E25: ='15W40'!E25 -> 137.79 | F25: ='15W40'!F25 -> 42 | G25: =F25*G4 -> 240.24 | H25: 8 | I25: =B25-C25 -> 111.7 | J25: =C25/B25 -> 0.77558114 | K25: =1-J25 -> 0.22441886 | M25: =B25-'15W40'!B25 -> 81.74 | N25: =C25-'15W40'!C25 -> 61.74
A26: Detroit With Fleetguard Filter (DD13,DD15.DD16) | B26: ='15W40'!B26+('15W40 Gallon'!G4-'15W40'!G4)*'15W40 Gallon'!F26+'15W40 Gallon'!M3 -> 475.73 | C26: =E26+G26+H26 -> 362.2928 | E26: ='15W40'!E26 -> 114.0528 | F26: ='15W40'!F26 -> 42 | G26: =F26*G4 -> 240.24 | H26: 8 | I26: =B26-C26 -> 113.4372 | J26: =C26/B26 -> 0.7615513 | K26: =1-J26 -> 0.2384487 | M26: =B26-'15W40'!B26 -> 81.74 | N26: =C26-'15W40'!C26 -> 61.74
A27: Detroit With Fleetguard | B27: ='15W40'!B27+('15W40 Gallon'!G4-'15W40'!G4)*'15W40 Gallon'!F27+'15W40 Gallon'!M2 -> 373.85 | C27: =E27+G27+H27 -> 270.7512 | E27: ='15W40'!E27 -> 45.3912 | F27: ='15W40'!F27 -> 38 | G27: =F27*G4 -> 217.36 | H27: 8 | I27: =B27-C27 -> 103.0988 | J27: =C27/B27 -> 0.72422415 | K27: =1-J27 -> 0.27577585 | M27: =B27-'15W40'!B27 -> 70.86 | N27: =C27-'15W40'!C27 -> 55.86
A28: Duramax / Vortec 8100L | B28: ='15W40'!B28+('15W40 Gallon'!G4-'15W40'!G4)*'15W40 Gallon'!F28+'15W40 Gallon'!M1 -> 201.57 | C28: =E28+G28+H28 -> 98.1824 | E28: ='15W40'!E28 -> 10.1024 | F28: ='15W40'!F28 -> 14 | G28: =F28*G4 -> 80.08 | H28: 8 | I28: =B28-C28 -> 103.3876 | J28: =C28/B28 -> 0.48708836 | K28: =1-J28 -> 0.51291164 | M28: =B28-'15W40'!B28 -> 30.58 | N28: =C28-'15W40'!C28 -> 20.58
A30: F250 / F350 / F550 / F650 | B30: ='15W40'!B30+('15W40 Gallon'!G4-'15W40'!G4)*'15W40 Gallon'!F30+'15W40 Gallon'!M1 -> 201.57 | C30: =E30+G30+H30 -> 102.4968 | E30: ='15W40'!E30 -> 14.4168 | F30: ='15W40'!F30 -> 14 | G30: =F30*G4 -> 80.08 | H30: 8 | I30: =B30-C30 -> 99.0732 | J30: =C30/B30 -> 0.50849234 | K30: =1-J30 -> 0.49150766 | M30: =B30-'15W40'!B30 -> 30.58 | N30: =C30-'15W40'!C30 -> 20.58
A32: Hino | B32: ='15W40'!B32+('15W40 Gallon'!G4-'15W40'!G4)*'15W40 Gallon'!F32+'15W40 Gallon'!M1 -> 300.57 | C32: =E32+G32+H32 -> 184.08 | E32: ='15W40'!E32 -> 96 | F32: ='15W40'!F32 -> 14 | G32: =F32*G4 -> 80.08 | H32: 8 | I32: =B32-C32 -> 116.49 | J32: =C32/B32 -> 0.61243637 | K32: =1-J32 -> 0.38756363 | M32: =B32-'15W40'!B32 -> 30.58 | N32: =C32-'15W40'!C32 -> 20.58
A33: Hino With Fleetguard | B33: ='15W40'!B33+('15W40 Gallon'!G4-'15W40'!G4)*'15W40 Gallon'!F33+'15W40 Gallon'!M1 -> 230.57 | C33: =E33+G33+H33 -> 115.5016 | E33: ='15W40'!E33 -> 27.4216 | F33: ='15W40'!F33 -> 14 | G33: =F33*G4 -> 80.08 | H33: 8 | I33: =B33-C33 -> 115.0684 | J33: =C33/B33 -> 0.50093941 | K33: =1-J33 -> 0.49906059 | M33: =B33-'15W40'!B33 -> 30.58 | N33: =C33-'15W40'!C33 -> 20.58
A35: International | B35: ='15W40'!B35+('15W40 Gallon'!G4-'15W40'!G4)*'15W40 Gallon'!F35+'15W40 Gallon'!M2 -> 319.21 | C35: =E35+G35+H35 -> 210.2888 | E35: ='15W40'!E35 -> 53.5688 | F35: ='15W40'!F35 -> 26 | G35: =F35*G4 -> 148.72 | H35: 8 | I35: =B35-C35 -> 108.9212 | J35: =C35/B35 -> 0.65877886 | K35: =1-J35 -> 0.34122114 | M35: =B35-'15W40'!B35 -> 53.22 | N35: =C35-'15W40'!C35 -> 38.22
A36: International S13 | B36: ='15W40'!B36+('15W40 Gallon'!G4-'15W40'!G4)*'15W40 Gallon'!F36+'15W40 Gallon'!M3 -> 587.61 | C36: =E36+G36+H36 -> 449.92 | E36: ='15W40'!E36 -> 178.8 | F36: ='15W40'!F36 -> 46 | G36: =F36*G4 -> 263.12 | H36: 8 | I36: =B36-C36 -> 137.69 | J36: =C36/B36 -> 0.76567792 | K36: =1-J36 -> 0.23432208 | N36: =C36-'15W40'!C36 -> 67.62
A37: International Vista | B37: ='15W40'!B37+('15W40 Gallon'!G4-'15W40'!G4)*'15W40 Gallon'!F37+'15W40 Gallon'!M4 -> 295.57 | C37: =E37+G37+H37 -> 145.9528 | E37: ='15W40'!E37 -> 57.8728 | F37: ='15W40'!F37 -> 14 | G37: =F37*G4 -> 80.08 | H37: 8 | I37: =B37-C37 -> 149.6172 | J37: =C37/B37 -> 0.49380113 | K37: =1-J37 -> 0.50619887
A38: Isuzu With Fleetguard Filter | B38: ='15W40'!B38+('15W40 Gallon'!G4-'15W40'!G4)*'15W40 Gallon'!F38+'15W40 Gallon'!M1 -> 246.57 | C38: =E38+G38+H38 -> 132.2208 | E38: ='15W40'!E38 -> 44.1408 | F38: ='15W40'!F38 -> 14 | G38: =F38*G4 -> 80.08 | H38: 8 | I38: =B38-C38 -> 114.3492 | J38: =C38/B38 -> 0.53624042 | K38: =1-J38 -> 0.46375958 | M38: =B38-'15W40'!B38 -> 30.58 | N38: =C38-'15W40'!C38 -> 20.58
A39: Isuzu | B39: ='15W40'!B39+('15W40 Gallon'!G4-'15W40'!G4)*'15W40 Gallon'!F39+'15W40 Gallon'!M1 -> 306.57 | C39: =E39+G39+H39 -> 157.05 | E39: ='15W40'!E39 -> 68.97 | F39: ='15W40'!F39 -> 14 | G39: =F39*G4 -> 80.08 | H39: 8 | I39: =B39-C39 -> 149.52 | J39: =C39/B39 -> 0.51228105 | K39: =1-J39 -> 0.48771895 | N39: =C39-'15W40'!C39 -> 20.58
A41: MP 7 / MP8 With Fleetguard Filter | B41: ='15W40'!B41+('15W40 Gallon'!G4-'15W40'!G4)*'15W40 Gallon'!F41+'15W40 Gallon'!M2 -> 434.85 | C41: =E41+G41+H41 -> 311.9648 | E41: ='15W40'!E41 -> 86.6048 | F41: ='15W40'!F41 -> 38 | G41: =F41*G4 -> 217.36 | H41: 8 | I41: =B41-C41 -> 122.8852 | J41: =C41/B41 -> 0.71740784 | K41: =1-J41 -> 0.28259216 | M41: =B41-'15W40'!B41 -> 70.86 | N41: =C41-'15W40'!C41 -> 55.86
A42: MP 7 / MP8 With Mack Filter | B42: ='15W40'!B42+('15W40 Gallon'!G4-'15W40'!G4)*'15W40 Gallon'!F42+'15W40 Gallon'!M2 -> 505.85 | C42: =E42+G42+H42 -> 398.86 | E42: ='15W40'!E42 -> 173.5 | F42: ='15W40'!F42 -> 38 | G42: =F42*G4 -> 217.36 | H42: 8 | I42: =B42-C42 -> 106.99 | J42: =C42/B42 -> 0.78849461 | K42: =1-J42 -> 0.21150539 | M42: =B42-'15W40'!B42 -> 70.86 | N42: =C42-'15W40'!C42 -> 55.86
A43: MP 7/MP8/ MP10 With Fleetguard ( 52L) | B43: ='15W40'!B43+('15W40 Gallon'!G4-'15W40'!G4)*'15W40 Gallon'!F43+'15W40 Gallon'!M4 -> 542.84 | C43: =E43+G43+H43 -> 409.2048 | E43: ='15W40'!E41 -> 86.6048 | F43: ='15W40'!F43 -> 55 | G43: =F43*G4 -> 314.6 | H43: 8 | I43: =B43-C43 -> 133.6352 | J43: =C43/B43 -> 0.75382212 | K43: =1-J43 -> 0.24617788 | M43: =B43-'15W40'!B43 -> 105.85 | N43: =C43-'15W40'!C43 -> 80.85
A44: MP 7/MP8/ MP10 With Mack (52L) | B44: ='15W40'!B44+('15W40 Gallon'!G4-'15W40'!G4)*'15W40 Gallon'!F44+'15W40 Gallon'!M4 -> 615.84 | C44: =E44+G44+H44 -> 496.1 | E44: ='15W40'!E44 -> 173.5 | F44: ='15W40'!F44 -> 55 | G44: =F44*G4 -> 314.6 | H44: 8 | I44: =B44-C44 -> 119.74 | J44: =C44/B44 -> 0.80556638 | K44: =1-J44 -> 0.19443362 | M44: =B44-'15W40'!B44 -> 105.85 | N44: =C44-'15W40'!C44 -> 80.85
A45: Mack With Fleetguard Filter | B45: ='15W40'!B45+('15W40 Gallon'!G4-'15W40'!G4)*'15W40 Gallon'!F45+'15W40 Gallon'!M2 -> 388.85 | C45: =E45+G45+H45 -> 275.744 | E45: ='15W40'!E45 -> 50.384 | F45: ='15W40'!F45 -> 38 | G45: =F45*G4 -> 217.36 | H45: 8 | I45: =B45-C45 -> 113.106 | J45: =C45/B45 -> 0.70912691 | K45: =1-J45 -> 0.29087309 | M45: =B45-'15W40'!B45 -> 70.86 | N45: =C45-'15W40'!C45 -> 55.86
A46: Mack With Fleetguard Filter(52L) | B46: ='15W40'!B46+('15W40 Gallon'!G4-'15W40'!G4)*'15W40 Gallon'!F46+'15W40 Gallon'!M4 -> 479.43 | C46: =E46+G46+H46 -> 355.824 | E46: ='15W40'!E46 -> 50.384 | F46: ='15W40'!F46 -> 52 | G46: =F46*G4 -> 297.44 | H46: 8 | I46: =B46-C46 -> 123.606 | J46: =C46/B46 -> 0.74218134 | K46: =1-J46 -> 0.25781866 | M46: =B46-'15W40'!B46 -> 101.44 | N46: =C46-'15W40'!C46 -> 76.44
A47: Mack With Mack Filter | B47: ='15W40'!B47+('15W40 Gallon'!G4-'15W40'!G4)*'15W40 Gallon'!F47+'15W40 Gallon'!M2 -> 497.85 | C47: =E47+G47+H47 -> 386.75 | E47: ='15W40'!E47 -> 161.39 | F47: ='15W40'!F47 -> 38 | G47: =F47*G4 -> 217.36 | H47: 8 | I47: =B47-C47 -> 111.1 | J47: =C47/B47 -> 0.77684041 | K47: =1-J47 -> 0.22315959 | M47: =B47-'15W40'!B47 -> 70.86 | N47: =C47-'15W40'!C47 -> 55.86
A48: Mack With Mack Filter( 52L ) | B48: ='15W40'!B48+('15W40 Gallon'!G4-'15W40'!G4)*'15W40 Gallon'!F48+'15W40 Gallon'!M4 -> 591.43 | C48: =E48+G48+H48 -> 466.83 | E48: ='15W40'!E48 -> 161.39 | F48: ='15W40'!F48 -> 52 | G48: =F48*G4 -> 297.44 | H48: 8 | I48: =B48-C48 -> 124.6 | J48: =C48/B48 -> 0.78932418 | K48: =1-J48 -> 0.21067582 | M48: =B48-'15W40'!B48 -> 101.44 | N48: =C48-'15W40'!C48 -> 76.44
...

Sheet 10W30
A1: STANDARD JOB LIST | B1: 10W30 | C1: Delo | G1: ='Oil Price'!C25 -> 4.41 | H1: 0.05 | L1: 8--20 | M1: 15
B2: selling | C2: cost | E2: Filtre | F2: Litre | G2: Oil | H2: Fuel | I2: Profit | J2: Cost | K2: Profit | L2: 21--38 | M2: 25
A3: Auto Greaser Refill | E3: Cost | G3: Cost | H3: Grease | L3: 39--46 | M3: 30
G4: =G1+H1 -> 4.46 | J4: 1 | L4: 47& UP | M4: 35
A6: C 7 / 10 / 3126 With Cat Filter | B6: ='15W40'!B6+M2 -> 290.99 | C6: =E6+G6+H6 -> 172.79 | E6: ='15W40'!E6 -> 53.29 | F6: ='15W40'!F6 -> 25 | G6: =F6*G4 -> 111.5 | H6: 8 | I6: =B6-C6 -> 118.2 | J6: =C6/B6 -> 0.59380047 | K6: =1-J6 -> 0.40619953
A7: C 7 / 10 / 3126 With Fleetguard Filter | B7: ='15W40'!B7+M2 -> 268.99 | C7: =E7+G7+H7 -> 141.2992 | E7: ='15W40'!E7 -> 21.7992 | F7: ='15W40'!F7 -> 25 | G7: =F7*G4 -> 111.5 | H7: 8 | I7: =B7-C7 -> 127.6908 | J7: =C7/B7 -> 0.52529536 | K7: =1-J7 -> 0.47470464
A9: C 12 / 3406 With Cat Filter | B9: ='15W40'!B9+M2 -> 359.99 | C9: =E9+G9+H9 -> 248.06 | E9: ='15W40'!E9 -> 70.58 | F9: ='15W40'!F9 -> 38 | G9: =F9*G4 -> 169.48 | H9: 8 | I9: =B9-C9 -> 111.93 | J9: =C9/B9 -> 0.6890747 | K9: =1-J9 -> 0.3109253
A10: C 12 / 3406 With Fleetguard Filter | B10: ='15W40'!B10+M2 -> 318.99 | C10: =E10+G10+H10 -> 208.5248 | E10: ='15W40'!E10 -> 31.0448 | F10: ='15W40'!F10 -> 38 | G10: =F10*G4 -> 169.48 | H10: 8 | I10: =B10-C10 -> 110.4652 | J10: =C10/B10 -> 0.65370325 | K10: =1-J10 -> 0.34629675
A12: C 13 / 15 With Cat Filter | B12: ='15W40'!B12+M3 -> 384.99 | C12: =E12+G12+H12 -> 270.36 | E12: ='15W40'!E12 -> 70.58 | F12: ='15W40'!F12 -> 43 | G12: =F12*G4 -> 191.78 | H12: 8 | I12: =B12-C12 -> 114.63 | J12: =C12/B12 -> 0.70225201 | K12: =1-J12 -> 0.29774799
A13: C 13 / 15 With Fleetguard Filter | B13: ='15W40'!B13+M3 -> 343.99 | C13: =E13+G13+H13 -> 230.8248 | E13: ='15W40'!E13 -> 31.0448 | F13: ='15W40'!F13 -> 43 | G13: =F13*G4 -> 191.78 | H13: 8 | I13: =B13-C13 -> 113.1652 | J13: =C13/B13 -> 0.67102183 | K13: =1-J13 -> 0.32897817
A15: Cummins N14 | B15: ='15W40'!B15+M3 -> 331.99 | C15: =E15+G15+H15 -> 217.8312 | E15: ='15W40'!E15 -> 31.4312 | F15: ='15W40'!F15 -> 40 | G15: =F15*G4 -> 178.4 | H15: 8 | I15: =B15-C15 -> 114.1588 | J15: =C15/B15 -> 0.65613784 | K15: =1-J15 -> 0.34386216
A16: Cummins 5.9L/6.7L | B16: ='15W40'!B16+M1 -> 185.99 | C16: =E16+G16+H16 -> 77.16 | E16: ='15W40'!E16 -> 6.72 | F16: ='15W40'!F16 -> 14 | G16: =F16*G4 -> 62.44 | H16: 8 | I16: =B16-C16 -> 108.83 | J16: =C16/B16 -> 0.41486101 | K16: =1-J16 -> 0.58513899
A17: Cummins ISC / ISL | B17: ='15W40'!B17+M2 -> 282.99 | C17: =E17+G17+H17 -> 170.3104 | E17: ='15W40'!E17 -> 50.8104 | F17: ='15W40'!F17 -> 25 | G17: =F17*G4 -> 111.5 | H17: 8 | I17: =B17-C17 -> 112.6796 | J17: =C17/B17 -> 0.6018248 | K17: =1-J17 -> 0.3981752
A18: Cummins ISB | B18: ='15W40'!B18+'10W30'!M2 -> 280.99 | C18: =E18+G18+H18 -> 146.188 | E18: ='15W40'!E18 -> 26.688 | F18: ='15W40'!F18 -> 25 | G18: =F18*G4 -> 111.5 | H18: 8 | I18: =B18-C18 -> 134.802 | J18: =C18/B18 -> 0.52026051 | K18: =1-J18 -> 0.47973949
A19: Cummins ISM | B19: ='15W40'!B19+M2 -> 317.99 | C19: =E19+G19+H19 -> 208.3944 | E19: ='15W40'!E19 -> 39.8344 | F19: ='15W40'!F19 -> 36 | G19: =F19*G4 -> 160.56 | H19: 8 | I19: =B19-C19 -> 109.5956 | J19: =C19/B19 -> 0.65534891 | K19: =1-J19 -> 0.34465109
A20: Cummins ISX | B20: ='15W40'!B20+M3 -> 408.99 | C20: =E20+G20+H20 -> 289.8896 | E20: ='15W40'!E20 -> 85.6496 | F20: ='15W40'!F20 -> 44 | G20: =F20*G4 -> 196.24 | H20: 8 | I20: =B20-C20 -> 119.1004 | J20: =C20/B20 -> 0.70879386 | K20: =1-J20 -> 0.29120614
A21: Cummins M11 | B21: ='15W40'!B21+M2 -> 300.99 | C21: =E21+G21+H21 -> 191.0712 | E21: ='15W40'!E21 -> 31.4312 | F21: ='15W40'!F21 -> 34 | G21: =F21*G4 -> 151.64 | H21: 8 | I21: =B21-C21 -> 109.9188 | J21: =C21/B21 -> 0.63480913 | K21: =1-J21 -> 0.36519087
A23: Detroit With Detroit Filter | B23: ='15W40'!B23+M2 -> 374.99 | C23: =E23+G23+H23 -> 255.1 | E23: ='15W40'!E23 -> 77.62 | F23: ='15W40'!F23 -> 38 | G23: =F23*G4 -> 169.48 | H23: 8 | I23: =B23-C23 -> 119.89 | J23: =C23/B23 -> 0.68028481 | K23: =1-J23 -> 0.31971519
A24: Detroit With Detroit Filter (DD8) | B24: ='15W40'!B24+M2 -> 434.99 | C24: =E24+G24+H24 -> 319.57 | E24: ='15W40'!E24 -> 168.85 | F24: ='15W40'!F24 -> 32 | G24: =F24*G4 -> 142.72 | H24: 8 | I24: =B24-C24 -> 115.42 | J24: =C24/B24 -> 0.73466057 | K24: =1-J24 -> 0.26533943
A25: Detroit With Detroit Filter (DD13,DD15,DD16) | B25: ='15W40'!B25+M3 -> 445.99 | C25: =E25+G25+H25 -> 333.11 | E25: ='15W40'!E25 -> 137.79 | F25: ='15W40'!F25 -> 42 | G25: =F25*G4 -> 187.32 | H25: 8 | I25: =B25-C25 -> 112.88 | J25: =C25/B25 -> 0.74690015 | K25: =1-J25 -> 0.25309985
A26: Detroit With Fleetguard Filter (DD13,DD15.DD16) | B26: ='15W40'!B26+'10W30'!M3 -> 423.99 | C26: =E26+G26+H26 -> 309.3728 | E26: ='15W40'!E26 -> 114.0528 | F26: ='15W40'!F26 -> 42 | G26: =F26*G4 -> 187.32 | H26: 8 | I26: =B26-C26 -> 114.6172 | J26: =C26/B26 -> 0.72967004 | K26: =1-J26 -> 0.27032996
A27: Detroit With Fleetguard | B27: ='15W40'!B27+M2 -> 327.99 | C27: =E27+G27+H27 -> 222.8712 | E27: ='15W40'!E27 -> 45.3912 | F27: ='15W40'!F27 -> 38 | G27: =F27*G4 -> 169.48 | H27: 8 | I27: =B27-C27 -> 105.1188 | J27: =C27/B27 -> 0.67950608 | K27: =1-J27 -> 0.32049392
A28: Duramax / Vortec 8100L | B28: ='15W40'!B28+M1 -> 185.99 | C28: =E28+G28+H28 -> 80.5424 | E28: ='15W40'!E28 -> 10.1024 | F28: ='15W40'!F28 -> 14 | G28: =F28*G4 -> 62.44 | H28: 8 | I28: =B28-C28 -> 105.4476 | J28: =C28/B28 -> 0.43304694 | K28: =1-J28 -> 0.56695306
A30: F250 / F350 / F550 / F650 | B30: ='15W40'!B30+M1 -> 185.99 | C30: =E30+G30+H30 -> 84.8568 | E30: ='15W40'!E30 -> 14.4168 | F30: ='15W40'!F30 -> 14 | G30: =F30*G4 -> 62.44 | H30: 8 | I30: =B30-C30 -> 101.1332 | J30: =C30/B30 -> 0.45624388 | K30: =1-J30 -> 0.54375612
A32: Hino | B32: ='15W40'!B32+M1 -> 284.99 | C32: =E32+G32+H32 -> 166.44 | E32: ='15W40'!E32 -> 96 | F32: ='15W40'!F32 -> 14 | G32: =F32*G4 -> 62.44 | H32: 8 | I32: =B32-C32 -> 118.55 | J32: =C32/B32 -> 0.58402049 | K32: =1-J32 -> 0.41597951
A33: Hino With Fleetguard | B33: ='15W40'!B33+M1 -> 214.99 | C33: =E33+G33+H33 -> 97.8616 | E33: ='15W40'!E33 -> 27.4216 | F33: ='15W40'!F33 -> 14 | G33: =F33*G4 -> 62.44 | H33: 8 | I33: =B33-C33 -> 117.1284 | J33: =C33/B33 -> 0.4551914 | K33: =1-J33 -> 0.5448086
A35: International | B35: ='15W40'!B35+M2 -> 290.99 | C35: =E35+G35+H35 -> 177.5288 | E35: ='15W40'!E35 -> 53.5688 | F35: ='15W40'!F35 -> 26 | G35: =F35*G4 -> 115.96 | H35: 8 | I35: =B35-C35 -> 113.4612 | J35: =C35/B35 -> 0.61008557 | K35: =1-J35 -> 0.38991443
A36: International S13 | B36: ='15W40'!B36+M3 -> 529.99 | C36: =E36+G36+H36 -> 391.96 | E36: ='15W40'!E36 -> 178.8 | F36: ='15W40'!F36 -> 46 | G36: =F36*G4 -> 205.16 | H36: 8 | I36: =B36-C36 -> 138.03 | J36: =C36/B36 -> 0.73956112 | K36: =1-J36 -> 0.26043888
A37: International Vista | B37: ='15W40'!B37+M1 -> 264.99 | C37: =E37+G37+H37 -> 128.3128 | E37: ='15W40'!E37 -> 57.8728 | F37: ='15W40'!F37 -> 14 | G37: =F37*G4 -> 62.44 | H37: 8 | I37: =B37-C37 -> 136.6772 | J37: =C37/B37 -> 0.48421752 | K37: =1-J37 -> 0.51578248
A38: Isuzu With Fleetguard Filter | B38: ='15W40'!B38+M1 -> 230.99 | C38: =E38+G38+H38 -> 114.5808 | E38: ='15W40'!E38 -> 44.1408 | F38: ='15W40'!F38 -> 14 | G38: =F38*G4 -> 62.44 | H38: 8 | I38: =B38-C38 -> 116.4092 | J38: =C38/B38 -> 0.49604225 | K38: =1-J38 -> 0.50395775
A39: Isuzu | B39: ='15W40'!B39+M1 -> 290.99 | C39: =E39+G39+H39 -> 139.41 | E39: ='15W40'!E39 -> 68.97 | F39: ='15W40'!F39 -> 14 | G39: =F39*G4 -> 62.44 | H39: 8 | I39: =B39-C39 -> 151.58 | J39: =C39/B39 -> 0.47908863 | K39: =1-J39 -> 0.52091137
A41: MP 7 / MP8 With Fleetguard | B41: ='15W40'!B41+M2 -> 388.99 | C41: =E41+G41+H41 -> 264.0848 | E41: ='15W40'!E41 -> 86.6048 | F41: ='15W40'!F41 -> 38 | G41: =F41*G4 -> 169.48 | H41: 8 | I41: =B41-C41 -> 124.9052 | J41: =C41/B41 -> 0.67889869 | K41: =1-J41 -> 0.32110131
A42: MP 7 / MP8 | B42: ='15W40'!B42+M2 -> 459.99 | C42: =E42+G42+H42 -> 350.98 | E42: ='15W40'!E42 -> 173.5 | F42: ='15W40'!F42 -> 38 | G42: =F42*G4 -> 169.48 | H42: 8 | I42: =B42-C42 -> 109.01 | J42: =C42/B42 -> 0.76301659 | K42: =1-J42 -> 0.23698341
A43: MP 7/MP8/ MP10 With Fleetguard ( 52L) | B43: ='15W40'!B43+'10W30'!M4 -> 471.99 | C43: =E43+G43+H43 -> 339.9048 | E43: ='15W40'!E43 -> 86.6048 | F43: ='15W40'!F43 -> 55 | G43: =F43*G4 -> 245.3 | H43: 8 | I43: =B43-C43 -> 132.0852 | J43: =C43/B43 -> 0.72015255 | K43: =1-J43 -> 0.27984745
A44: MP 7/MP8/ MP10 With Mack (52L) | B44: ='15W40'!B44+'10W30'!M4 -> 544.99 | C44: =E44+G44+H44 -> 426.8 | E44: ='15W40'!E44 -> 173.5 | F44: ='15W40'!F44 -> 55 | G44: =F44*G4 -> 245.3 | H44: 8 | I44: =B44-C44 -> 118.19 | J44: =C44/B44 -> 0.78313364 | K44: =1-J44 -> 0.21686636
A45: Mack With Fleetguard Filter | B45: ='15W40'!B45+M2 -> 342.99 | C45: =E45+G45+H45 -> 227.864 | E45: ='15W40'!E45 -> 50.384 | F45: ='15W40'!F45 -> 38 | G45: =F45*G4 -> 169.48 | H45: 8 | I45: =B45-C45 -> 115.126 | J45: =C45/B45 -> 0.6643459 | K45: =1-J45 -> 0.3356541
A46: Mack With Fleetguard Filter(52L) | B46: ='15W40'!B46+M4 -> 412.99 | C46: =E46+G46+H46 -> 290.304 | E46: ='15W40'!E46 -> 50.384 | F46: ='15W40'!F46 -> 52 | G46: =F46*G4 -> 231.92 | H46: 8 | I46: =B46-C46 -> 122.686 | J46: =C46/B46 -> 0.70293227 | K46: =1-J46 -> 0.29706773
A47: Mack With Mack Filter | B47: ='15W40'!B47+M2 -> 451.99 | C47: =E47+G47+H47 -> 338.87 | E47: ='15W40'!E47 -> 161.39 | F47: ='15W40'!F47 -> 38 | G47: =F47*G4 -> 169.48 | H47: 8 | I47: =B47-C47 -> 113.12 | J47: =C47/B47 -> 0.74972898 | K47: =1-J47 -> 0.25027102
A48: Mack With Mack Filter( 52L ) | B48: ='15W40'!B48+M4 -> 524.99 | C48: =E48+G48+H48 -> 401.31 | E48: ='15W40'!E48 -> 161.39 | F48: ='15W40'!F48 -> 52 | G48: =F48*G4 -> 231.92 | H48: 8 | I48: =B48-C48 -> 123.68 | J48: =C48/B48 -> 0.76441456 | K48: =1-J48 -> 0.23558544
A50: Max Force 7 | B50: ='15W40'!B50+M2 -> 460.99 | C50: =E50+G50+H50 -> 346.64 | E50: ='15W40'!E50 -> 222.68 | F50: ='15W40'!F50 -> 26 | G50: =F50*G4 -> 115.96 | H50: 8 | I50: =B50-C50 -> 114.35 | J50: =C50/B50 -> 0.7519469 | K50: =1-J50 -> 0.2480531
...

Sheet 10W30 Gallon
A1: STANDARD JOB LIST | B1: 10W30 Gallon | D1: Delo | G1: ='Oil Price'!F25 -> 6.3835979 | H1: 0.05 | L1: 8--20 | M1: 10
B2: selling | C2: cost | E2: Filtre | F2: Litre | G2: Oil | H2: Fuel | I2: Profit | J2: Cost | K2: Profit | L2: 21--38 | M2: 15
A3: Auto Greaser Refill | E3: Cost | G3: Cost | H3: Grease | L3: 39--46 | M3: 20 | N3: Price Diff | O3: Cost Diff
G4: =G1+H1 -> 6.4335979 | J4: 1 | L4: 47& UP | M4: 25
A6: C 7 / 10 / 3126 With Cat Filter | B6: ='10W30'!B6+('10W30 Gallon'!G4-'10W30'!G4)*'10W30 Gallon'!F6+'10W30 Gallon'!M2 -> 355.32995 | C6: =E6+G6+H6 -> 222.12995 | E6: ='15W40'!E6 -> 53.29 | F6: ='15W40'!F6 -> 25 | G6: =F6*G4 -> 160.83995 | H6: 8 | I6: =B6-C6 -> 133.2 | J6: =C6/B6 -> 0.62513714 | K6: =1-J6 -> 0.37486286 | N6: =B6-'10W30'!B6 -> 64.339947 | O6: =C6-'10W30'!C6 -> 49.339947
A7: C 7 / 10 / 3126 With Fleetguard Filter | B7: ='10W30'!B7+('10W30 Gallon'!G4-'10W30'!G4)*'10W30 Gallon'!F7+'10W30 Gallon'!M2 -> 333.32995 | C7: =E7+G7+H7 -> 190.63915 | E7: ='15W40'!E7 -> 21.7992 | F7: ='15W40'!F7 -> 25 | G7: =F7*G4 -> 160.83995 | H7: 8 | I7: =B7-C7 -> 142.6908 | J7: =C7/B7 -> 0.57192325 | K7: =1-J7 -> 0.42807675 | N7: =B7-'10W30'!B7 -> 64.339947 | O7: =C7-'10W30'!C7 -> 49.339947
A9: C 12 / 3406 With Cat Filter | B9: ='10W30'!B9+('10W30 Gallon'!G4-'10W30'!G4)*'10W30 Gallon'!F9+'10W30 Gallon'!M2 -> 449.98672 | C9: =E9+G9+H9 -> 323.05672 | E9: ='15W40'!E9 -> 70.58 | F9: ='15W40'!F9 -> 38 | G9: =F9*G4 -> 244.47672 | H9: 8 | I9: =B9-C9 -> 126.93 | J9: =C9/B9 -> 0.71792501 | K9: =1-J9 -> 0.28207499 | N9: =B9-'10W30'!B9 -> 89.99672 | O9: =C9-'10W30'!C9 -> 74.99672
